Workbook

Sheet WBS
A1: Portfolio Project — WBS (AI Support Ticket System) - 7-Week
A2: Project start date (Monday): | C2: 46302
A3: Legend: edit only the yellow start date and the Status column (yellow). Blue numbers = estimated hours (6.5 h/day, split evenly). Everything else is formulas.
A5: WBS ID | B5: Level | C5: Work item | D5: Type | E5: Week | F5: Day | G5: Start | H5: Finish | I5: Est. hours | J5: Status | K5: % complete | L5: Earned hours | M5: Notes | N5: Watch (YouTube search) | O5: Read (docs / article)
A6: 1 | B6: 1 | C6: AI Support Ticket System portfolio project | D6: Project | G6: =G7 -> 46302 | H6: =H146 -> 46350 | I6: =SUM(I7,I30,I49,I69,I89,I109,I127) -> 227.7 | K6: =IF(I6=0,0,L6/I6) -> 0.15696091 | L6: =SUM(L7,L30,L49,L69,L89,L109,L127) -> 35.74
A7: 1.1 | B7: 2 | C7: Week 1: Foundations | D7: Phase | E7: 1 | G7: =G8 -> 46302 | H7: =H8 -> 46302 | I7: =SUM(I8,I13,I17,I21,I25) -> 32.49 | K7: =IF(I7=0,0,L7/I7) -> 1 | L7: =SUM(L8,L13,L17,L21,L25) -> 32.49
A8: 1.1.1 | B8: 3 | C8: Day 1: Environment | D8: Work package | E8: 1 | F8: 1 | G8: =WORKDAY($C$2,F8-1) -> 46302 | H8: =G8 -> 46302 | I8: =SUM(I9:I12) -> 6.48 | J8: =IF(COUNTIF(J9:J12,"Done")+COUNTIF(J9:J12,"Cut")=4,"Done",IF(COUNTIF(J9:J12,"Not started")=4,"Not started","In progress")) -> Done | K8: =IF(I8=0,0,L8/I8) -> 1 | L8: =SUM(L9:L12) -> 6.48
A9: 1.1.1.1 | B9: 4 | C9: Read what changed in the latest Laravel release | D9: Task | E9: 1 | F9: 1 | G9: =G8 -> 46302 | H9: =H8 -> 46302 | I9: 1.62 | J9: Done | K9: =IF(J9="Done",1,IF(J9="In progress",0.5,0)) -> 1 | L9: =I9*K9 -> 1.62 | N9: =HYPERLINK("https://www.youtube.com/results?search_query=Laravel+13+new+features","YouTube: Laravel 13 new features") -> YouTube: Laravel 13 new features | O9: =HYPERLINK("https://laravel.com/docs/releases","Laravel docs: Release notes") -> Laravel docs: Release notes
A10: 1.1.1.2 | B10: 4 | C10: Create public GitHub repo; Docker Compose with PHP, PostgreSQL (pgvector), Redis | D10: Task | E10: 1 | F10: 1 | G10: =G8 -> 46302 | H10: =H8 -> 46302 | I10: 1.62 | J10: Done | K10: =IF(J10="Done",1,IF(J10="In progress",0.5,0)) -> 1 | L10: =I10*K10 -> 1.62 | N10: =HYPERLINK("https://www.youtube.com/results?search_query=docker+compose+laravel+postgres+redis","YouTube: docker compose laravel postgres redis") -> YouTube: docker compose laravel postgres redis | O10: =HYPERLINK("https://docs.docker.com/compose/","Docker docs: Compose") -> Docker docs: Compose
A11: 1.1.1.3 | B11: 4 | C11: Install Laravel; confirm app, database and Redis connect | D11: Task | E11: 1 | F11: 1 | G11: =G8 -> 46302 | H11: =H9 -> 46302 | I11: 1.62 | J11: Done | K11: =IF(J11="Done",1,IF(J11="In progress",0.5,0)) -> 1 | L11: =I11*K11 -> 1.62 | N11: =HYPERLINK("https://www.youtube.com/results?search_query=laravel+docker+setup+postgresql","YouTube: laravel docker setup postgresql") -> YouTube: laravel docker setup postgresql | O11: =HYPERLINK("https://laravel.com/docs/installation","Laravel docs: Installation") -> Laravel docs: Installation
A12: 1.1.1.4 | B12: 4 | C12: First commit + DEVLOG.md | D12: Task | E12: 1 | F12: 1 | G12: =G8 -> 46302 | H12: =H8 -> 46302 | I12: 1.62 | J12: Done | K12: =IF(J12="Done",1,IF(J12="In progress",0.5,0)) -> 1 | L12: =I12*K12 -> 1.62 | N12: =HYPERLINK("https://www.youtube.com/results?search_query=git+basics+tutorial","YouTube: git basics tutorial") -> YouTube: git basics tutorial | O12: =HYPERLINK("https://git-scm.com/book/en/v2","Pro Git book") -> Pro Git book
A13: 1.1.2 | B13: 3 | C13: Day 2: Domain design | D13: Work package | E13: 1 | F13: 2 | G13: =WORKDAY($C$2,F13-1) -> 46303 | H13: =G13 -> 46303 | I13: =SUM(I14:I16) -> 6.51 | J13: =IF(COUNTIF(J14:J16,"Done")+COUNTIF(J14:J16,"Cut")=3,"Done",IF(COUNTIF(J14:J16,"Not started")=3,"Not started","In progress")) -> Done | K13: =IF(I13=0,0,L13/I13) -> 1 | L13: =SUM(L14:L16) -> 6.51
A14: 1.1.2.1 | B14: 4 | C14: Draw ERD: organizations, users, roles, tickets, messages, categories, SLA policies, KB articles | D14: Task | E14: 1 | F14: 2 | G14: =G13 -> 46303 | H14: =H13 -> 46303 | I14: 2.17 | J14: Done | K14: =IF(J14="Done",1,IF(J14="In progress",0.5,0)) -> 1 | L14: =I14*K14 -> 2.17 | N14: =HYPERLINK("https://www.youtube.com/results?search_query=database+design+entity+relationship+diagram","YouTube: database design entity relationship diagram") -> YouTube: database design entity relationship diagram | O14: =HYPERLINK("https://mermaid.js.org/syntax/entityRelationshipDiagram.html","Mermaid: ER diagrams") -> Mermaid: ER diagrams
A15: 1.1.2.2 | B15: 4 | C15: Write ADR-001: multi-tenancy approach | D15: Task | E15: 1 | F15: 2 | G15: =G13 -> 46303 | H15: =H13 -> 46303 | I15: 2.17 | J15: Done | K15: =IF(J15="Done",1,IF(J15="In progress",0.5,0)) -> 1 | L15: =I15*K15 -> 2.17 | N15: =HYPERLINK("https://www.youtube.com/results?search_query=multi+tenancy+single+database+vs+database+per+tenant","YouTube: multi tenancy single database vs database per tenant") -> YouTube: multi tenancy single database vs database per tenant | O15: =HYPERLINK("https://learn.microsoft.com/en-us/azure/architecture/guide/multitenant/considerations/tenancy-models","Azure: Tenancy models") -> Azure: Tenancy models
A16: 1.1.2.3 | B16: 4 | C16: Migrations, models, relationships, factories | D16: Task | E16: 1 | F16: 2 | G16: =G13 -> 46303 | H16: =H13 -> 46303 | I16: 2.17 | J16: Done | K16: =IF(J16="Done",1,IF(J16="In progress",0.5,0)) -> 1 | L16: =I16*K16 -> 2.17 | N16: =HYPERLINK("https://www.youtube.com/results?search_query=laravel+eloquent+relationships+factories","YouTube: laravel eloquent relationships factories") -> YouTube: laravel eloquent relationships factories | O16: =HYPERLINK("https://laravel.com/docs/eloquent-relationships","Laravel docs: Relationships") -> Laravel docs: Relationships
A17: 1.1.3 | B17: 3 | C17: Day 3: Auth and roles | D17: Work package | E17: 1 | F17: 3 | G17: =WORKDAY($C$2,F17-1) -> 46304 | H17: =G17 -> 46304 | I17: =SUM(I18:I20) -> 6.51 | J17: =IF(COUNTIF(J18:J20,"Done")+COUNTIF(J18:J20,"Cut")=3,"Done",IF(COUNTIF(J18:J20,"Not started")=3,"Not started","In progress")) -> Done | K17: =IF(I17=0,0,L17/I17) -> 1 | L17: =SUM(L18:L20) -> 6.51
A18: 1.1.3.1 | B18: 4 | C18: Install Laravel React starter kit (Inertia + TypeScript) for auth | D18: Task | E18: 1 | F18: 3 | G18: =G17 -> 46304 | H18: =H17 -> 46304 | I18: 2.17 | J18: Done | K18: =IF(J18="Done",1,IF(J18="In progress",0.5,0)) -> 1 | L18: =I18*K18 -> 2.17 | N18: =HYPERLINK("https://www.youtube.com/results?search_query=laravel+react+starter+kit+inertia","YouTube: laravel react starter kit inertia") -> YouTube: laravel react starter kit inertia | O18: =HYPERLINK("https://laravel.com/docs/starter-kits","Laravel docs: Starter kits") -> Laravel docs: Starter kits
A19: 1.1.3.2 | B19: 4 | C19: Roles (admin, agent, customer) and ticket policies | D19: Task | E19: 1 | F19: 3 | G19: =G17 -> 46304 | H19: =H17 -> 46304 | I19: 2.17 | J19: Done | K19: =IF(J19="Done",1,IF(J19="In progress",0.5,0)) -> 1 | L19: =I19*K19 -> 2.17 | N19: =HYPERLINK("https://www.youtube.com/results?search_query=laravel+policies+gates+authorization","YouTube: laravel policies gates authorization") -> YouTube: laravel policies gates authorization | O19: =HYPERLINK("https://laravel.com/docs/authorization","Laravel docs: Authorization") -> Laravel docs: Authorization
A20: 1.1.3.3 | B20: 4 | C20: Tenant middleware: scope every request to the user's organization | D20: Task | E20: 1 | F20: 3 | G20: =G17 -> 46304 | H20: =H17 -> 46304 | I20: 2.17 | J20: Done | K20: =IF(J20="Done",1,IF(J20="In progress",0.5,0)) -> 1 | L20: =I20*K20 -> 2.17 | N20: =HYPERLINK("https://www.youtube.com/results?search_query=laravel+multi+tenancy+global+scope+subdomain","YouTube: laravel multi tenancy global scope subdomain") -> YouTube: laravel multi tenancy global scope subdomain | O20: =HYPERLINK("https://laravel.com/docs/eloquent#global-scopes","Laravel docs: Global scopes") -> Laravel docs: Global scopes
A21: 1.1.4 | B21: 3 | C21: Day 4: Pest | D21: Work package | E21: 1 | F21: 4 | G21: =WORKDAY($C$2,F21-1) -> 46307 | H21: =G21 -> 46307 | I21: =SUM(I22:I24) -> 6.51 | J21: =IF(COUNTIF(J22:J24,"Done")+COUNTIF(J22:J24,"Cut")=3,"Done",IF(COUNTIF(J22:J24,"Not started")=3,"Not started","In progress")) -> Done | K21: =IF(I21=0,0,L21/I21) -> 1 | L21: =SUM(L22:L24) -> 6.51
A22: 1.1.4.1 | B22: 4 | C22: Learn Pest basics: it(), expect(), datasets, RefreshDatabase | D22: Task | E22: 1 | F22: 4 | G22: =G21 -> 46307 | H22: =H21 -> 46307 | I22: 2.17 | J22: Done | K22: =IF(J22="Done",1,IF(J22="In progress",0.5,0)) -> 1 | L22: =I22*K22 -> 2.17 | N22: =HYPERLINK("https://www.youtube.com/results?search_query=laravel+testing+tutorial","YouTube: laravel testing tutorial") -> YouTube: laravel testing tutorial | O22: =HYPERLINK("https://laravel.com/docs/testing","Laravel docs: Testing") -> Laravel docs: Testing
A23: 1.1.4.2 | B23: 4 | C23: Tests: tenant isolation | D23: Task | E23: 1 | F23: 4 | G23: =G21 -> 46307 | H23: =H21 -> 46307 | I23: 2.17 | J23: Done | K23: =IF(J23="Done",1,IF(J23="In progress",0.5,0)) -> 1 | L23: =I23*K23 -> 2.17 | N23: =HYPERLINK("https://www.youtube.com/results?search_query=laravel+multi+tenancy+testing+data+isolation","YouTube: laravel multi tenancy testing data isolation") -> YouTube: laravel multi tenancy testing data isolation | O23: =HYPERLINK("https://laravel.com/docs/database-testing","Laravel docs: Database testing") -> Laravel docs: Database testing
A24: 1.1.4.3 | B24: 4 | C24: Tests: role permissions | D24: Task | E24: 1 | F24: 4 | G24: =G21 -> 46307 | H24: =H21 -> 46307 | I24: 2.17 | J24: Done | K24: =IF(J24="Done",1,IF(J24="In progress",0.5,0)) -> 1 | L24: =I24*K24 -> 2.17 | N24: =HYPERLINK("https://www.youtube.com/results?search_query=laravel+testing+authorization+policies","YouTube: laravel testing authorization policies") -> YouTube: laravel testing authorization policies | O24: =HYPERLINK("https://laravel.com/docs/http-tests","Laravel docs: HTTP tests") -> Laravel docs: HTTP tests
A25: 1.1.5 | B25: 3 | C25: Day 5: Code quality + review | D25: Work package | E25: 1 | F25: 5 | G25: =WORKDAY($C$2,F25-1) -> 46308 | H25: =G25 -> 46308 | I25: =SUM(I26:I29) -> 6.48 | J25: =IF(COUNTIF(J26:J29,"Done")+COUNTIF(J26:J29,"Cut")=4,"Done",IF(COUNTIF(J26:J29,"Not started")=4,"Not started","In progress")) -> Done | K25: =IF(I25=0,0,L25/I25) -> 1 | L25: =SUM(L26:L29) -> 6.48
A26: 1.1.5.1 | B26: 4 | C26: Add Pint and Larastan; fix findings | D26: Task | E26: 1 | F26: 5 | G26: =G25 -> 46308 | H26: =H25 -> 46308 | I26: 1.62 | J26: Done | K26: =IF(J26="Done",1,IF(J26="In progress",0.5,0)) -> 1 | L26: =I26*K26 -> 1.62 | N26: =HYPERLINK("https://www.youtube.com/results?search_query=larastan+phpstan+laravel","YouTube: larastan phpstan laravel") -> YouTube: larastan phpstan laravel | O26: =HYPERLINK("https://github.com/larastan/larastan","Larastan on GitHub") -> Larastan on GitHub
A27: 1.1.5.2 | B27: 4 | C27: Move ticket logic into action classes | D27: Task | E27: 1 | F27: 5 | G27: =G25 -> 46308 | H27: =H25 -> 46308 | I27: 1.62 | J27: Done | K27: =IF(J27="Done",1,IF(J27="In progress",0.5,0)) -> 1 | L27: =I27*K27 -> 1.62 | N27: =HYPERLINK("https://www.youtube.com/results?search_query=laravel+action+classes+pattern","YouTube: laravel action classes pattern") -> YouTube: laravel action classes pattern | O27: =HYPERLINK("https://www.google.com/search?q=laravel+action+classes+pattern","Search: laravel action classes pattern") -> Search: laravel action classes pattern
A28: 1.1.5.3 | B28: 4 | C28: Seeders: 2 organizations, users per role, sample tickets | D28: Task | E28: 1 | F28: 5 | G28: =G25 -> 46308 | H28: =H25 -> 46308 | I28: 1.62 | J28: Done | K28: =IF(J28="Done",1,IF(J28="In progress",0.5,0)) -> 1 | L28: =I28*K28 -> 1.62 | N28: =HYPERLINK("https://www.youtube.com/results?search_query=laravel+seeders+factories","YouTube: laravel seeders factories") -> YouTube: laravel seeders factories | O28: =HYPERLINK("https://laravel.com/docs/seeding","Laravel docs: Seeding") -> Laravel docs: Seeding
A29: 1.1.5.4 | B29: 4 | C29: Week review: tests green, README stub | D29: Task | E29: 1 | F29: 5 | G29: =G25 -> 46308 | H29: =H25 -> 46308 | I29: 1.62 | J29: Done | K29: =IF(J29="Done",1,IF(J29="In progress",0.5,0)) -> 1 | L29: =I29*K29 -> 1.62 | N29: =HYPERLINK("https://www.youtube.com/results?search_query=how+to+write+a+good+README+github","YouTube: how to write a good README github") -> YouTube: how to write a good README github | O29: =HYPERLINK("https://www.makeareadme.com/","Make a README") -> Make a README
A30: 1.2 | B30: 2 | C30: Week 2: Frontend | D30: Phase | E30: 2 | G30: =G31 -> 46309 | H30: =H45 -> 46315 | I30: =SUM(I31,I34,I37,I41,I45) -> 32.53 | K30: =IF(I30=0,0,L30/I30) -> 0.099907777 | L30: =SUM(L31,L34,L37,L41,L45) -> 3.25
A31: 1.2.1 | B31: 3 | C31: Day 6: TypeScript | D31: Work package | E31: 2 | F31: 6 | G31: =WORKDAY($C$2,F31-1) -> 46309 | H31: =G31 -> 46309 | I31: =SUM(I32:I33) -> 6.5 | J31: =IF(COUNTIF(J32:J33,"Done")+COUNTIF(J32:J33,"Cut")=2,"Done",IF(COUNTIF(J32:J33,"Not started")=2,"Not started","In progress")) -> In progress | K31: =IF(I31=0,0,L31/I31) -> 0.5 | L31: =SUM(L32:L33) -> 3.25
A32: 1.2.1.1 | B32: 4 | C32: Learn types, interfaces, unions, generics, typing React props/events | D32: Task | E32: 2 | F32: 6 | G32: =G31 -> 46309 | H32: =H31 -> 46309 | I32: 3.25 | J32: Not started | K32: =IF(J32="Done",1,IF(J32="In progress",0.5,0)) -> 0 | L32: =I32*K32 -> 0 | N32: =HYPERLINK("https://www.youtube.com/results?search_query=typescript+tutorial+for+beginners","YouTube: typescript tutorial for beginners") -> YouTube: typescript tutorial for beginners | O32: =HYPERLINK("https://www.typescriptlang.org/docs/handbook/intro.html","TypeScript Handbook") -> TypeScript Handbook
A33: 1.2.1.2 | B33: 4 | C33: Shared types for Ticket, Message, User | D33: Task | E33: 2 | F33: 6 | G33: =G31 -> 46309 | H33: =H31 -> 46309 | I33: 3.25 | J33: Done | K33: =IF(J33="Done",1,IF(J33="In progress",0.5,0)) -> 1 | L33: =I33*K33 -> 3.25 | N33: =HYPERLINK("https://www.youtube.com/results?search_query=typescript+react+props+types","YouTube: typescript react props types") -> YouTube: typescript react props types | O33: =HYPERLINK("https://react.dev/learn/typescript","React docs: Using TypeScript") -> React docs: Using TypeScript
A34: 1.2.2 | B34: 3 | C34: Day 7: Inertia + ticket list | D34: Work package | E34: 2 | F34: 7 | G34: =WORKDAY($C$2,F34-1) -> 46310 | H34: =G34 -> 46310 | I34: =SUM(I35:I36) -> 6.5 | J34: =IF(COUNTIF(J35:J36,"Done")+COUNTIF(J35:J36,"Cut")=2,"Done",IF(COUNTIF(J35:J36,"Not started")=2,"Not started","In progress")) -> Not started | K34: =IF(I34=0,0,L34/I34) -> 0 | L34: =SUM(L35:L36) -> 0
A35: 1.2.2.1 | B35: 4 | C35: Learn Inertia: pages, props, layouts, shared data, useForm | D35: Task | E35: 2 | F35: 7 | G35: =G34 -> 46310 | H35: =H34 -> 46310 | I35: 3.25 | J35: Not started | K35: =IF(J35="Done",1,IF(J35="In progress",0.5,0)) -> 0 | L35: =I35*K35 -> 0 | N35: =HYPERLINK("https://www.youtube.com/results?search_query=inertia.js+laravel+react+tutorial","YouTube: inertia.js laravel react tutorial") -> YouTube: inertia.js laravel react tutorial | O35: =HYPERLINK("https://inertiajs.com/pages","Inertia docs: Pages") -> Inertia docs: Pages
A36: 1.2.2.2 | B36: 4 | C36: Ticket list page: pagination, filters, search | D36: Task | E36: 2 | F36: 7 | G36: =G34 -> 46310 | H36: =H34 -> 46310 | I36: 3.25 | J36: Done | K36: =IF(J36="Done",1,IF(J36="In progress",0.5,0)) -> 0 | L36: =I36*K36 -> 0 | N36: =HYPERLINK("https://www.youtube.com/results?search_query=laravel+inertia+pagination+filters+search","YouTube: laravel inertia pagination filters search") -> YouTube: laravel inertia pagination filters search | O36: =HYPERLINK("https://laravel.com/docs/pagination","Laravel docs: Pagination") -> Laravel docs: Pagination
A37: 1.2.3 | B37: 3 | C37: Day 8: Create + detail | D37: Work package | E37: 2 | F37: 8 | G37: =WORKDAY($C$2,F37-1) -> 46311 | H37: =G37 -> 46311 | I37: =SUM(I38:I40) -> 6.51 | J37: =IF(COUNTIF(J38:J40,"Done")+COUNTIF(J38:J40,"Cut")=3,"Done",IF(COUNTIF(J38:J40,"Not started")=3,"Not started","In progress")) -> Not started | K37: =IF(I37=0,0,L37/I37) -> 0 | L37: =SUM(L38:L40) -> 0
A38: 1.2.3.1 | B38: 4 | C38: Create ticket form with validation errors | D38: Task | E38: 2 | F38: 8 | G38: =G37 -> 46311 | H38: =H37 -> 46311 | I38: 2.17 | J38: Done | K38: =IF(J38="Done",1,IF(J38="In progress",0.5,0)) -> 0 | L38: =I38*K38 -> 0 | N38: =HYPERLINK("https://www.youtube.com/results?search_query=inertia+useForm+validation+errors+react","YouTube: inertia useForm validation errors react") -> YouTube: inertia useForm validation errors react | O38: =HYPERLINK("https://inertiajs.com/forms","Inertia docs: Forms") -> Inertia docs: Forms
A39: 1.2.3.2 | B39: 4 | C39: Ticket detail page with message thread and replies | D39: Task | E39: 2 | F39: 8 | G39: =G37 -> 46311 | H39: =H37 -> 46311 | I39: 2.17 | J39: Done | K39: =IF(J39="Done",1,IF(J39="In progress",0.5,0)) -> 0 | L39: =I39*K39 -> 0 | N39: =HYPERLINK("https://www.youtube.com/results?search_query=laravel+inertia+react+crud","YouTube: laravel inertia react crud") -> YouTube: laravel inertia react crud | O39: =HYPERLINK("https://laravel.com/docs/eloquent-relationships#eager-loading","Laravel docs: Eager loading") -> Laravel docs: Eager loading
A40: 1.2.3.3 | B40: 4 | C40: File attachments (local storage) | D40: Task | E40: 2 | F40: 8 | G40: =G37 -> 46311 | H40: =H37 -> 46311 | I40: 2.17 | J40: Not started | K40: =IF(J40="Done",1,IF(J40="In progress",0.5,0)) -> 0 | L40: =I40*K40 -> 0 | N40: =HYPERLINK("https://www.youtube.com/results?search_query=laravel+file+upload+inertia+react","YouTube: laravel file upload inertia react") -> YouTube: laravel file upload inertia react | O40: =HYPERLINK("https://laravel.com/docs/filesystem","Laravel docs: File storage") -> Laravel docs: File storage
A41: 1.2.4 | B41: 3 | C41: Day 9: Agent view | D41: Work package | E41: 2 | F41: 9 | G41: =WORKDAY($C$2,F41-1) -> 46314 | H41: =G41 -> 46314 | I41: =SUM(I42:I44) -> 6.51 | J41: =IF(COUNTIF(J42:J44,"Done")+COUNTIF(J42:J44,"Cut")=3,"Done",IF(COUNTIF(J42:J44,"Not started")=3,"Not started","In progress")) -> Not started | K41: =IF(I41=0,0,L41/I41) -> 0 | L41: =SUM(L42:L44) -> 0
...

Sheet Summary
A1: Progress by week
A3: Week | B3: Phase | C3: Start | D3: Finish | E3: Est. hours | F3: Earned hours | G3: % complete | H3: Tasks done | I3: Tasks total
A4: 1 | B4: =WBS!C7 -> Week 1: Foundations | C4: =WBS!G7 -> 46302 | D4: =WBS!H7 -> 46302 | E4: =WBS!I7 -> 32.49 | F4: =WBS!L7 -> 32.49 | G4: =IF(E4=0,0,F4/E4) -> 1 | H4: =COUNTIFS(WBS!$E$6:$E$146,A4,WBS!$D$6:$D$146,"Task",WBS!$J$6:$J$146,"Done") -> 17 | I4: =COUNTIFS(WBS!$E$6:$E$146,A4,WBS!$D$6:$D$146,"Task") -> 17
A5: 2 | B5: =WBS!C30 -> Week 2: Frontend | C5: =WBS!G30 -> 46309 | D5: =WBS!H30 -> 46315 | E5: =WBS!I30 -> 32.53 | F5: =WBS!L30 -> 3.25 | G5: =IF(E5=0,0,F5/E5) -> 0.099907777 | H5: =COUNTIFS(WBS!$E$6:$E$146,A5,WBS!$D$6:$D$146,"Task",WBS!$J$6:$J$146,"Done") -> 1 | I5: =COUNTIFS(WBS!$E$6:$E$146,A5,WBS!$D$6:$D$146,"Task") -> 13
A6: 3 | B6: =WBS!C49 -> Week 3: Business logic | C6: =WBS!G49 -> 46316 | D6: =WBS!H49 -> 46322 | E6: =WBS!I49 -> 32.54 | F6: =WBS!L49 -> 0 | G6: =IF(E6=0,0,F6/E6) -> 0 | H6: =COUNTIFS(WBS!$E$6:$E$146,A6,WBS!$D$6:$D$146,"Task",WBS!$J$6:$J$146,"Done") -> 0 | I6: =COUNTIFS(WBS!$E$6:$E$146,A6,WBS!$D$6:$D$146,"Task") -> 14
A7: 4 | B7: =WBS!C69 -> Week 4: Python + FastAPI | C7: =WBS!G69 -> 46323 | D7: =WBS!H69 -> 46329 | E7: =WBS!I69 -> 32.54 | F7: =WBS!L69 -> 0 | G7: =IF(E7=0,0,F7/E7) -> 0 | H7: =COUNTIFS(WBS!$E$6:$E$146,A7,WBS!$D$6:$D$146,"Task",WBS!$J$6:$J$146,"Done") -> 0 | I7: =COUNTIFS(WBS!$E$6:$E$146,A7,WBS!$D$6:$D$146,"Task") -> 14
A8: 5 | B8: =WBS!C89 -> Week 5: AI features | C8: =WBS!G89 -> 46330 | D8: =WBS!H89 -> 46336 | E8: =WBS!I89 -> 32.54 | F8: =WBS!L89 -> 0 | G8: =IF(E8=0,0,F8/E8) -> 0 | H8: =COUNTIFS(WBS!$E$6:$E$146,A8,WBS!$D$6:$D$146,"Task",WBS!$J$6:$J$146,"Done") -> 0 | I8: =COUNTIFS(WBS!$E$6:$E$146,A8,WBS!$D$6:$D$146,"Task") -> 14
A9: 6 | B9: =WBS!C109 -> Week 6: Senior-grade quality | C9: =WBS!G109 -> 46337 | D9: =WBS!H109 -> 46343 | E9: =WBS!I109 -> 32.52 | F9: =WBS!L109 -> 0 | G9: =IF(E9=0,0,F9/E9) -> 0 | H9: =COUNTIFS(WBS!$E$6:$E$146,A9,WBS!$D$6:$D$146,"Task",WBS!$J$6:$J$146,"Done") -> 0 | I9: =COUNTIFS(WBS!$E$6:$E$146,A9,WBS!$D$6:$D$146,"Task") -> 12
A10: 7 | B10: =WBS!C127 -> Week 7: Deploy + showcase | C10: =WBS!G127 -> 46344 | D10: =WBS!H127 -> 46350 | E10: =WBS!I127 -> 32.54 | F10: =WBS!L127 -> 0 | G10: =IF(E10=0,0,F10/E10) -> 0 | H10: =COUNTIFS(WBS!$E$6:$E$146,A10,WBS!$D$6:$D$146,"Task",WBS!$J$6:$J$146,"Done") -> 0 | I10: =COUNTIFS(WBS!$E$6:$E$146,A10,WBS!$D$6:$D$146,"Task") -> 14
B11: Total | C11: =C4 -> 46302 | D11: =D10 -> 46350 | E11: =SUM(E4:E10) -> 227.7 | F11: =SUM(F4:F10) -> 35.74 | G11: =IF(E11=0,0,F11/E11) -> 0.15696091 | H11: =SUM(H4:H10) -> 18 | I11: =SUM(I4:I10) -> 98
A13: % complete counts In progress tasks as 50%. Status 'Cut' tasks count as not earned.
